Workbook

Sheet ANS 2,3
B1: Q2
A2: vehicle | B2: price | C2: quantity sold | D2: sales | F2: total sum
A3: car | B3: 500000 | C3: 10 | D3: =B3*C3 -> 5000000 | F3: =SUM(Table1[[#This Row],[sales]],D4) -> 5157500
A4: bicycle | B4: 10500 | C4: 15 | D4: =B4*C4 -> 157500
A5: auto-rickshaw | B5: 25000 | C5: 29 | D5: =B5*C5 -> 725000
B8: Q3
A9: Items | B9: price | C9: sales
A10: item A | B10: 90 | C10: 1000 | F10: AVG SALES, (100<PRICE>300)
A11: item B | B11: 150 | C11: 1200 | F11: =AVERAGEIFS(Table2[sales],Table2[price],">100",Table2[price],"<300") -> 1350
A12: item C | B12: 250 | C12: 1500

Sheet ANS 4,5,6
A1: OrderID | B1: CustomerName | C1: Region | D1: Product | E1: Quantity | F1: UnitPrice | G1: OrderDate
A2: 1001 | B2: Amit Sharma | C2: North | D2: Notebook | E2: 10 | F2: 50 | G2: 45413 | I2: Q4. | J2: TOTAL CUSTOMER NO
A3: 1002 | B3: Neha Verma | C3: South | D3: Pen | E3: 20 | F3: 10 | G3: 45444 | J3: =COUNTA(B2:B51) -> 50
A4: 1003 | B4: Rahul Singh | C4: East | D4: Marker | E4: 15 | F4: 25 | G4: 45474
A5: 1004 | B5: Pooja Mehta | C5: West | D5: Notebook | E5: 5 | F5: 50 | G5: 45505 | I5: Q5. | J5: TOTAL SALES | L5: Q6. | M5: total sales (notebook,north)
A6: 1005 | B6: Ankit Jain | C6: North | D6: Pencil | E6: 30 | F6: 5 | G6: 45566 | J6: =E2*F2 -> 500 | M6: =SUMIFS(J6:J55,D2:D51,"notebook",C2:C51,"north") -> 2900
A7: 1006 | B7: Sneha Patel | C7: South | D7: Notebook | E7: 12 | F7: 50 | G7: 45597 | J7: =F3*E3 -> 200 | M7: =SUMIFS(J7:J56,D3:D52,"notebook",C3:C52,"north") -> 2400
A8: 1007 | B8: Vikas Gupta | C8: East | D8: Eraser | E8: 25 | F8: 8 | G8: 13-01-2024 | J8: =F4*E4 -> 375 | M8: =SUMIFS(J8:J57,D4:D53,"notebook",C4:C53,"north") -> 2400
A9: 1008 | B9: Meera Nair | C9: West | D9: Pen | E9: 18 | F9: 10 | G9: 15-01-2024 | J9: =F5*E5 -> 250 | M9: =SUMIFS(J9:J58,D5:D54,"notebook",C5:C54,"north") -> 2400
A10: 1009 | B10: Anjali Rao | C10: North | D10: Marker | E10: 22 | F10: 25 | G10: 17-01-2024 | J10: =F6*E6 -> 150 | M10: =SUMIFS(J10:J59,D6:D55,"notebook",C6:C55,"north") -> 2400
A11: 1010 | B11: Manoj Das | C11: South | D11: Notebook | E11: 8 | F11: 50 | G11: 18-01-2024 | J11: =F7*E7 -> 600 | M11: =SUMIFS(J11:J60,D7:D56,"notebook",C7:C56,"north") -> 2400
A12: 1011 | B12: Ritika Sen | C12: East | D12: Pencil | E12: 40 | F12: 5 | G12: 19-01-2024 | J12: =F8*E8 -> 200 | M12: =SUMIFS(J12:J61,D8:D57,"notebook",C8:C57,"north") -> 2400
A13: 1012 | B13: Karan Malhotra | C13: West | D13: Eraser | E13: 35 | F13: 8 | G13: 20-01-2024 | J13: =F9*E9 -> 180 | M13: =SUMIFS(J13:J62,D9:D58,"notebook",C9:C58,"north") -> 2400
A14: 1013 | B14: Aryan Joshi | C14: North | D14: Notebook | E14: 14 | F14: 50 | G14: 22-01-2024 | J14: =F10*E10 -> 550 | M14: =SUMIFS(J14:J63,D10:D59,"notebook",C10:C59,"north") -> 2400
A15: 1014 | B15: Divya Kapoor | C15: South | D15: Pen | E15: 28 | F15: 10 | G15: 23-01-2024 | J15: =F11*E11 -> 400 | M15: =SUMIFS(J15:J64,D11:D60,"notebook",C11:C60,"north") -> 2400
A16: 1015 | B16: Sahil Arora | C16: East | D16: Marker | E16: 12 | F16: 25 | G16: 24-01-2024 | J16: =F12*E12 -> 200 | M16: =SUMIFS(J16:J65,D12:D61,"notebook",C12:C61,"north") -> 2400
A17: 1016 | B17: Muskan Jain | C17: West | D17: Pencil | E17: 25 | F17: 5 | G17: 26-01-2024 | J17: =F13*E13 -> 280 | M17: =SUMIFS(J17:J66,D13:D62,"notebook",C13:C62,"north") -> 2400
A18: 1017 | B18: Rohan Gupta | C18: North | D18: Eraser | E18: 20 | F18: 8 | G18: 28-01-2024 | J18: =F14*E14 -> 700 | M18: =SUMIFS(J18:J67,D14:D63,"notebook",C14:C63,"north") -> 2400
A19: 1018 | B19: Nidhi Sharma | C19: South | D19: Notebook | E19: 10 | F19: 50 | G19: 29-01-2024 | J19: =F15*E15 -> 280 | M19: =SUMIFS(J19:J68,D15:D64,"notebook",C15:C64,"north") -> 1700
A20: 1019 | B20: Tarun Verma | C20: East | D20: Pen | E20: 15 | F20: 10 | G20: 30-01-2024 | J20: =F16*E16 -> 300 | M20: =SUMIFS(J20:J69,D16:D65,"notebook",C16:C65,"north") -> 1700
A21: 1020 | B21: Simran Kaur | C21: West | D21: Marker | E21: 18 | F21: 25 | G21: 45293 | J21: =F17*E17 -> 125 | M21: =SUMIFS(J21:J70,D17:D66,"notebook",C17:C66,"north") -> 1700
A22: 1021 | B22: Deepak Rao | C22: North | D22: Notebook | E22: 9 | F22: 50 | G22: 45324 | J22: =F18*E18 -> 160 | M22: =SUMIFS(J22:J71,D18:D67,"notebook",C18:C67,"north") -> 1700
A23: 1022 | B23: Payal Mehta | C23: South | D23: Pencil | E23: 35 | F23: 5 | G23: 45353 | J23: =F19*E19 -> 500 | M23: =SUMIFS(J23:J72,D19:D68,"notebook",C19:C68,"north") -> 1700
A24: 1023 | B24: Aditya Singh | C24: East | D24: Eraser | E24: 30 | F24: 8 | G24: 45384 | J24: =F20*E20 -> 150 | M24: =SUMIFS(J24:J73,D20:D69,"notebook",C20:C69,"north") -> 1700
A25: 1024 | B25: Shreya Nair | C25: West | D25: Notebook | E25: 11 | F25: 50 | G25: 45445 | J25: =F21*E21 -> 450 | M25: =SUMIFS(J25:J74,D21:D70,"notebook",C21:C70,"north") -> 1700
A26: 1025 | B26: Sanjay Kumar | C26: North | D26: Pen | E26: 14 | F26: 10 | G26: 45475 | J26: =F22*E22 -> 450 | M26: =SUMIFS(J26:J75,D22:D71,"notebook",C22:C71,"north") -> 1700
A27: 1026 | B27: Aarti Sharma | C27: South | D27: Marker | E27: 16 | F27: 25 | G27: 45506 | J27: =F23*E23 -> 175 | M27: =SUMIFS(J27:J76,D23:D72,"notebook",C23:C72,"north") -> 1250
A28: 1027 | B28: Rajesh Patel | C28: East | D28: Pencil | E28: 22 | F28: 5 | G28: 45537 | J28: =F24*E24 -> 240 | M28: =SUMIFS(J28:J77,D24:D73,"notebook",C24:C73,"north") -> 1250
A29: 1028 | B29: Preeti Joshi | C29: West | D29: Eraser | E29: 27 | F29: 8 | G29: 45567 | J29: =F25*E25 -> 550 | M29: =SUMIFS(J29:J78,D25:D74,"notebook",C25:C74,"north") -> 1250
A30: 1029 | B30: Anurag Mishra | C30: North | D30: Notebook | E30: 13 | F30: 50 | G30: 45628 | J30: =F26*E26 -> 140 | M30: =SUMIFS(J30:J79,D26:D75,"notebook",C26:C75,"north") -> 1250
A31: 1030 | B31: Sanya Kapoor | C31: South | D31: Pen | E31: 32 | F31: 10 | G31: 13-02-2024 | J31: =F27*E27 -> 400 | M31: =SUMIFS(J31:J80,D27:D76,"notebook",C27:C76,"north") -> 1250
A32: 1031 | B32: Harsh Yadav | C32: East | D32: Marker | E32: 10 | F32: 25 | G32: 14-02-2024 | J32: =F28*E28 -> 110 | M32: =SUMIFS(J32:J81,D28:D77,"notebook",C28:C77,"north") -> 1250
A33: 1032 | B33: Kajal Rani | C33: West | D33: Pencil | E33: 18 | F33: 5 | G33: 16-02-2024 | J33: =F29*E29 -> 216 | M33: =SUMIFS(J33:J82,D29:D78,"notebook",C29:C78,"north") -> 1250
A34: 1033 | B34: Varun Sharma | C34: North | D34: Eraser | E34: 22 | F34: 8 | G34: 17-02-2024 | J34: =F30*E30 -> 650 | M34: =SUMIFS(J34:J83,D30:D79,"notebook",C30:C79,"north") -> 1250
A35: 1034 | B35: Swati Arora | C35: South | D35: Notebook | E35: 17 | F35: 50 | G35: 18-02-2024 | J35: =F31*E31 -> 320 | M35: =SUMIFS(J35:J84,D31:D80,"notebook",C31:C80,"north") -> 600
A36: 1035 | B36: Akhil Jain | C36: East | D36: Pen | E36: 19 | F36: 10 | G36: 19-02-2024 | J36: =F32*E32 -> 250 | M36: =SUMIFS(J36:J85,D32:D81,"notebook",C32:C81,"north") -> 600
A37: 1036 | B37: Priyanka Das | C37: West | D37: Marker | E37: 15 | F37: 25 | G37: 21-02-2024 | J37: =F33*E33 -> 90 | M37: =SUMIFS(J37:J86,D33:D82,"notebook",C33:C82,"north") -> 600
A38: 1037 | B38: Ravi Nair | C38: North | D38: Pencil | E38: 28 | F38: 5 | G38: 22-02-2024 | J38: =F34*E34 -> 176 | M38: =SUMIFS(J38:J87,D34:D83,"notebook",C34:C83,"north") -> 600
A39: 1038 | B39: Komal Singh | C39: South | D39: Eraser | E39: 24 | F39: 8 | G39: 23-02-2024 | J39: =F35*E35 -> 850 | M39: =SUMIFS(J39:J88,D35:D84,"notebook",C35:C84,"north") -> 600
A40: 1039 | B40: Ayesha Khan | C40: East | D40: Notebook | E40: 16 | F40: 50 | G40: 25-02-2024 | J40: =F36*E36 -> 190 | M40: =SUMIFS(J40:J89,D36:D85,"notebook",C36:C85,"north") -> 600
...

Sheet ANS 7
A3: PRODUCTS | B3: SALES
A4: Notebook | B4: ='ANS 4,5,6'!E2*'ANS 4,5,6'!F2 -> 500
A5: Pen | B5: ='ANS 4,5,6'!E3*'ANS 4,5,6'!F3 -> 200
A6: Marker | B6: ='ANS 4,5,6'!E4*'ANS 4,5,6'!F4 -> 375
A7: Notebook | B7: ='ANS 4,5,6'!E5*'ANS 4,5,6'!F5 -> 250 | F7: Row Labels | G7: Sum of SALES
A8: Pencil | B8: ='ANS 4,5,6'!E6*'ANS 4,5,6'!F6 -> 150 | F8: Eraser | G8: 1928
A9: Notebook | B9: ='ANS 4,5,6'!E7*'ANS 4,5,6'!F7 -> 600 | F9: Marker | G9: 3650
A10: Eraser | B10: ='ANS 4,5,6'!E8*'ANS 4,5,6'!F8 -> 200 | F10: Notebook | G10: 7550
A11: Pen | B11: ='ANS 4,5,6'!E9*'ANS 4,5,6'!F9 -> 180 | F11: Pen | G11: 2180
A12: Marker | B12: ='ANS 4,5,6'!E10*'ANS 4,5,6'!F10 -> 550 | F12: Pencil | G12: 1235
A13: Notebook | B13: ='ANS 4,5,6'!E11*'ANS 4,5,6'!F11 -> 400 | F13: Grand Total | G13: 16543
A14: Pencil | B14: ='ANS 4,5,6'!E12*'ANS 4,5,6'!F12 -> 200
A15: Eraser | B15: ='ANS 4,5,6'!E13*'ANS 4,5,6'!F13 -> 280
A16: Notebook | B16: ='ANS 4,5,6'!E14*'ANS 4,5,6'!F14 -> 700
A17: Pen | B17: ='ANS 4,5,6'!E15*'ANS 4,5,6'!F15 -> 280
A18: Marker | B18: ='ANS 4,5,6'!E16*'ANS 4,5,6'!F16 -> 300
A19: Pencil | B19: ='ANS 4,5,6'!E17*'ANS 4,5,6'!F17 -> 125
A20: Eraser | B20: ='ANS 4,5,6'!E18*'ANS 4,5,6'!F18 -> 160
A21: Notebook | B21: ='ANS 4,5,6'!E19*'ANS 4,5,6'!F19 -> 500
A22: Pen | B22: ='ANS 4,5,6'!E20*'ANS 4,5,6'!F20 -> 150
A23: Marker | B23: ='ANS 4,5,6'!E21*'ANS 4,5,6'!F21 -> 450
A24: Notebook | B24: ='ANS 4,5,6'!E22*'ANS 4,5,6'!F22 -> 450
A25: Pencil | B25: ='ANS 4,5,6'!E23*'ANS 4,5,6'!F23 -> 175
... A53: Pen | B53: ='ANS 4,5,6'!E51*'ANS 4,5,6'!F51 -> 250

Sheet ANS 8
B1: DATE | C1: QTY | D1: PRICE | E1: PRODUCT | F1: SALES
B2: 45413 | C2: 10 | D2: 50 | E2: 45413 | F2: =Table6[[#This Row],[QTY]]*Table6[[#This Row],[PRICE]] -> 500 | H2: DATE | I2: Sum of SALES
B3: 45444 | C3: 20 | D3: 10 | E3: 45444 | F3: =Table6[[#This Row],[QTY]]*Table6[[#This Row],[PRICE]] -> 200 | H3: 13-01-2024 | I3: 200
B4: 45474 | C4: 15 | D4: 25 | E4: 45474 | F4: =Table6[[#This Row],[QTY]]*Table6[[#This Row],[PRICE]] -> 375 | H4: 13-02-2024 | I4: 320
B5: 45505 | C5: 5 | D5: 50 | E5: 45505 | F5: =Table6[[#This Row],[QTY]]*Table6[[#This Row],[PRICE]] -> 250 | H5: 14-02-2024 | I5: 250
B6: 45566 | C6: 30 | D6: 5 | E6: 45566 | F6: =Table6[[#This Row],[QTY]]*Table6[[#This Row],[PRICE]] -> 150 | H6: 15-01-2024 | I6: 180
B7: 45597 | C7: 12 | D7: 50 | E7: 45597 | F7: =Table6[[#This Row],[QTY]]*Table6[[#This Row],[PRICE]] -> 600 | H7: 16-02-2024 | I7: 90
B8: 13-01-2024 | C8: 25 | D8: 8 | E8: 13-01-2024 | F8: =Table6[[#This Row],[QTY]]*Table6[[#This Row],[PRICE]] -> 200 | H8: 17-01-2024 | I8: 550
B9: 15-01-2024 | C9: 18 | D9: 10 | E9: 15-01-2024 | F9: =Table6[[#This Row],[QTY]]*Table6[[#This Row],[PRICE]] -> 180 | H9: 17-02-2024 | I9: 176
B10: 17-01-2024 | C10: 22 | D10: 25 | E10: 17-01-2024 | F10: =Table6[[#This Row],[QTY]]*Table6[[#This Row],[PRICE]] -> 550 | H10: 18-01-2024 | I10: 400
B11: 18-01-2024 | C11: 8 | D11: 50 | E11: 18-01-2024 | F11: =Table6[[#This Row],[QTY]]*Table6[[#This Row],[PRICE]] -> 400 | H11: 18-02-2024 | I11: 850
B12: 19-01-2024 | C12: 40 | D12: 5 | E12: 19-01-2024 | F12: =Table6[[#This Row],[QTY]]*Table6[[#This Row],[PRICE]] -> 200 | H12: 19-01-2024 | I12: 200
B13: 20-01-2024 | C13: 35 | D13: 8 | E13: 20-01-2024 | F13: =Table6[[#This Row],[QTY]]*Table6[[#This Row],[PRICE]] -> 280 | H13: 19-02-2024 | I13: 190
B14: 22-01-2024 | C14: 14 | D14: 50 | E14: 22-01-2024 | F14: =Table6[[#This Row],[QTY]]*Table6[[#This Row],[PRICE]] -> 700 | H14: 20-01-2024 | I14: 280
B15: 23-01-2024 | C15: 28 | D15: 10 | E15: 23-01-2024 | F15: =Table6[[#This Row],[QTY]]*Table6[[#This Row],[PRICE]] -> 280 | H15: 21-02-2024 | I15: 375
B16: 24-01-2024 | C16: 12 | D16: 25 | E16: 24-01-2024 | F16: =Table6[[#This Row],[QTY]]*Table6[[#This Row],[PRICE]] -> 300 | H16: 22-01-2024 | I16: 700
B17: 26-01-2024 | C17: 25 | D17: 5 | E17: 26-01-2024 | F17: =Table6[[#This Row],[QTY]]*Table6[[#This Row],[PRICE]] -> 125 | H17: 22-02-2024 | I17: 140
B18: 28-01-2024 | C18: 20 | D18: 8 | E18: 28-01-2024 | F18: =Table6[[#This Row],[QTY]]*Table6[[#This Row],[PRICE]] -> 160 | H18: 23-01-2024 | I18: 280
B19: 29-01-2024 | C19: 10 | D19: 50 | E19: 29-01-2024 | F19: =Table6[[#This Row],[QTY]]*Table6[[#This Row],[PRICE]] -> 500 | H19: 23-02-2024 | I19: 192
B20: 30-01-2024 | C20: 15 | D20: 10 | E20: 30-01-2024 | F20: =Table6[[#This Row],[QTY]]*Table6[[#This Row],[PRICE]] -> 150 | H20: 24-01-2024 | I20: 300
B21: 45293 | C21: 18 | D21: 25 | E21: 45293 | F21: =Table6[[#This Row],[QTY]]*Table6[[#This Row],[PRICE]] -> 450 | H21: 25-02-2024 | I21: 800
B22: 45324 | C22: 9 | D22: 50 | E22: 45324 | F22: =Table6[[#This Row],[QTY]]*Table6[[#This Row],[PRICE]] -> 450 | H22: 26-01-2024 | I22: 125
B23: 45353 | C23: 35 | D23: 5 | E23: 45353 | F23: =Table6[[#This Row],[QTY]]*Table6[[#This Row],[PRICE]] -> 175 | H23: 26-02-2024 | I23: 270
B24: 45384 | C24: 30 | D24: 8 | E24: 45384 | F24: =Table6[[#This Row],[QTY]]*Table6[[#This Row],[PRICE]] -> 240 | H24: 27-02-2024 | I24: 525
B25: 45445 | C25: 11 | D25: 50 | E25: 45445 | F25: =Table6[[#This Row],[QTY]]*Table6[[#This Row],[PRICE]] -> 550 | H25: 28-01-2024 | I25: 160
B26: 45475 | C26: 14 | D26: 10 | E26: 45475 | F26: =Table6[[#This Row],[QTY]]*Table6[[#This Row],[PRICE]] -> 140 | H26: 28-02-2024 | I26: 150
B27: 45506 | C27: 16 | D27: 25 | E27: 45506 | F27: =Table6[[#This Row],[QTY]]*Table6[[#This Row],[PRICE]] -> 400 | H27: 29-01-2024 | I27: 500
B28: 45537 | C28: 22 | D28: 5 | E28: 45537 | F28: =Table6[[#This Row],[QTY]]*Table6[[#This Row],[PRICE]] -> 110 | H28: 30-01-2024 | I28: 150
B29: 45567 | C29: 27 | D29: 8 | E29: 45567 | F29: =Table6[[#This Row],[QTY]]*Table6[[#This Row],[PRICE]] -> 216 | H29: 45293 | I29: 450
B30: 45628 | C30: 13 | D30: 50 | E30: 45628 | F30: =Table6[[#This Row],[QTY]]*Table6[[#This Row],[PRICE]] -> 650 | H30: 45294 | I30: 208
B31: 13-02-2024 | C31: 32 | D31: 10 | E31: 13-02-2024 | F31: =Table6[[#This Row],[QTY]]*Table6[[#This Row],[PRICE]] -> 320 | H31: 45324 | I31: 450
B32: 14-02-2024 | C32: 10 | D32: 25 | E32: 14-02-2024 | F32: =Table6[[#This Row],[QTY]]*Table6[[#This Row],[PRICE]] -> 250 | H32: 45325 | I32: 700
B33: 16-02-2024 | C33: 18 | D33: 5 | E33: 16-02-2024 | F33: =Table6[[#This Row],[QTY]]*Table6[[#This Row],[PRICE]] -> 90 | H33: 45353 | I33: 175
B34: 17-02-2024 | C34: 22 | D34: 8 | E34: 17-02-2024 | F34: =Table6[[#This Row],[QTY]]*Table6[[#This Row],[PRICE]] -> 176 | H34: 45354 | I34: 200
B35: 18-02-2024 | C35: 17 | D35: 50 | E35: 18-02-2024 | F35: =Table6[[#This Row],[QTY]]*Table6[[#This Row],[PRICE]] -> 850 | H35: 45384 | I35: 240
B36: 19-02-2024 | C36: 19 | D36: 10 | E36: 19-02-2024 | F36: =Table6[[#This Row],[QTY]]*Table6[[#This Row],[PRICE]] -> 190 | H36: 45385 | I36: 425
B37: 21-02-2024 | C37: 15 | D37: 25 | E37: 21-02-2024 | F37: =Table6[[#This Row],[QTY]]*Table6[[#This Row],[PRICE]] -> 375 | H37: 45413 | I37: 500
B38: 22-02-2024 | C38: 28 | D38: 5 | E38: 22-02-2024 | F38: =Table6[[#This Row],[QTY]]*Table6[[#This Row],[PRICE]] -> 140 | H38: 45415 | I38: 95
B39: 23-02-2024 | C39: 24 | D39: 8 | E39: 23-02-2024 | F39: =Table6[[#This Row],[QTY]]*Table6[[#This Row],[PRICE]] -> 192 | H39: 45444 | I39: 200
B40: 25-02-2024 | C40: 16 | D40: 50 | E40: 25-02-2024 | F40: =Table6[[#This Row],[QTY]]*Table6[[#This Row],[PRICE]] -> 800 | H40: 45445 | I40: 550
...
